2024-03-14 09:58:46,011 Start MPyC runtime v0.9
2024-03-14 09:58:46,114 All 4 parties connected.
ic| E: 25
ic| G.number_of_nodes(): 15
ic| G.number_of_edges(): 25
ic| f'{mpc.pid + 1} of {L} party': '4 of 3 party'
ic| len(adj_mat): 4, len(adj_mat[0]): 225
ic| '初始化数组I'
2024-03-14 09:58:46,198 Exception in callback _SelectorSocketTransport._call_connection_lost(None)
handle: <Handle _SelectorSocketTransport._call_connection_lost(None)>
Traceback (most recent call last):
  File "/usr/lib/python3.10/asyncio/events.py", line 80, in _run
    self._context.run(self._callback, *self._args)
  File "/usr/lib/python3.10/asyncio/selector_events.py", line 984, in _call_connection_lost
    super()._call_connection_lost(exc)
  File "/usr/lib/python3.10/asyncio/selector_events.py", line 742, in _call_connection_lost
    self._protocol.connection_lost(exc)
  File "/home/xzq/.local/lib/python3.10/site-packages/mpyc/asyncoro.py", line 152, in connection_lost
    rt.parties[rt.pid].protocol.set_result(None)
asyncio.exceptions.InvalidStateError: invalid state
Traceback (most recent call last):
  File "/home/xzq/Secure-Graph/no_db_demo/mpc_firmcore_mat.py", line 107, in <module>
    mpc.run(firmcore(2))
  File "/home/xzq/.local/lib/python3.10/site-packages/mpyc/runtime.py", line 181, in run
    return self._loop.run_until_complete(f)
  File "/usr/lib/python3.10/asyncio/base_events.py", line 649, in run_until_complete
    return future.result()
  File "/home/xzq/Secure-Graph/no_db_demo/mpc_firmcore_mat.py", line 53, in firmcore
    I[i] = mpc.sorted(per_id)[-lamb]  # id为i的顶点在各层的第λ大的度
  File "/home/xzq/.local/lib/python3.10/site-packages/mpyc/seclists.py", line 105, in __setitem__
    value = self.sectype(value)
  File "/home/xzq/.local/lib/python3.10/site-packages/mpyc/sectypes.py", line 533, in __init__
    raise TypeError('None, int, or finite field element required')
TypeError: None, int, or finite field element required
